<!DOCTYPE html>
<html>
<head>
    <title>ptest html report</title>
    <meta http-equiv="Content-Type" content="text/html;charset=utf-8"/>
    <meta name="description" content="ptest test results."/>
    <link href="report.css" rel="stylesheet" type="text/css"/>
    <style id="extra-style" type="text/css"></style>
</head>
<body>
<div id="meta">
    Generated by <a href="https://pypi.python.org/pypi/ptest">ptest</a> at 2017-07-19 16:45:15.374052
    <br/><span id="system-info">andersons-iMac.local / Python 3.5.3 / Darwin-16.6.0-x86_64-i386-64bit</span>
</div>
<h1>Test Results</h1>

<div class="main-container">
    <div class="panel navigation">
        <div class="panel-heading">
            <div class="filter-btn all" filter="all">ALL<span class="badge"></span></div>
            <div class="filter-btn passed" filter="passed">PASS<span class="badge"></span></div>
            <div class="filter-btn failed" filter="failed">FAIL<span class="badge"></span></div>
            <div class="filter-btn skipped" filter="skipped">SKIP<span class="badge"></span></div>
        </div>
        <div class="panel-body">
            <div class="toolbar">
                <span class="expand-all">ExpandAll</span>
                <span class="collapse-all">CollapseAll</span>
            </div>
            <div class="tree">
                <ul></ul>
            </div>
        </div>
        <div id="splitter"></div>
    </div>
    <div class="panel detail">
        <div class="panel-heading">
            <span class="text"></span>
        </div>
        <div class="panel-body"></div>
    </div>
</div>
<script type="text/javascript" src="report.js"></script>
<script type="text/javascript">
    // init test suite data
    var testSuite = {"type": "suite", "skipped": 1, "elapsedTime": 5.368949, "testModules": [{"type": "module", "skipped": 1, "testModules": [{"type": "module", "skipped": 1, "testModules": [{"type": "module", "skipped": 1, "testModules": [], "testClasses": [{"type": "class", "skipped": 1, "passed": 0, "description": "", "failed": 0, "runMode": "singleline", "startTime": "2017-07-19 16:45:09.906938", "elapsedTime": 5.368032, "endTime": "2017-07-19 16:45:15.274970", "runGroup": null, "name": "LoginTest", "testCases": [{"type": "case", "test": {"description": "", "type": "fixture", "screenshots": [], "elapsedTime": 0.000107, "fixtureType": "Test", "status": "skipped", "name": "pass_one_lesson", "logs": [{"level": "warning", "message": "@BeforeMethod&nbsp;failed,&nbsp;so&nbsp;skipped."}], "startTime": "2017-07-19 16:45:15.248435", "fullName": "autotest.cases.test_passcourse.LoginTest.pass_one_lesson@Test", "endTime": "2017-07-19 16:45:15.248542"}, "afterMethod": {"description": "Clean up", "type": "fixture", "screenshots": [{"source": "Web&nbsp;Driver", "path": "autotest.cases.test_passcourse.LoginTest.pass_one_lesson@AfterMethod-1.png"}], "elapsedTime": 0.025469, "fixtureType": "AfterMethod", "status": "failed", "name": "after", "logs": [{"level": "info", "message": "cleaning&nbsp;up"}, {"level": "error", "message": "Failed&nbsp;with&nbsp;following&nbsp;message:<br/>Traceback&nbsp;(most&nbsp;recent&nbsp;call&nbsp;last):<br/>&nbsp;&nbsp;File&nbsp;&quot;/Users/anderson/.pyenv/versions/3.5.3/lib/python3.5/site-packages/ptest/testexecutor.py&quot;,&nbsp;line&nbsp;399,&nbsp;in&nbsp;run_test_configuration<br/>&nbsp;&nbsp;&nbsp;&nbsp;self.test_fixture.test_fixture_ref.__call__()<br/>&nbsp;&nbsp;File&nbsp;&quot;/Users/anderson/testcode/mobile_test/mynewthinking/autotest/cases/test_passcourse.py&quot;,&nbsp;line&nbsp;46,&nbsp;in&nbsp;after<br/>&nbsp;&nbsp;&nbsp;&nbsp;self.login.driver.quit()<br/>AttributeError:&nbsp;'LoginTest'&nbsp;object&nbsp;has&nbsp;no&nbsp;attribute&nbsp;'login'<br/>"}, {"level": "warning", "message": "Failed&nbsp;to&nbsp;take&nbsp;the&nbsp;screenshot.<br/>Traceback&nbsp;(most&nbsp;recent&nbsp;call&nbsp;last):<br/>&nbsp;&nbsp;File&nbsp;&quot;/Users/anderson/.pyenv/versions/3.5.3/lib/python3.5/site-packages/ptest/testexecutor.py&quot;,&nbsp;line&nbsp;399,&nbsp;in&nbsp;run_test_configuration<br/>&nbsp;&nbsp;&nbsp;&nbsp;self.test_fixture.test_fixture_ref.__call__()<br/>&nbsp;&nbsp;File&nbsp;&quot;/Users/anderson/testcode/mobile_test/mynewthinking/autotest/cases/test_passcourse.py&quot;,&nbsp;line&nbsp;46,&nbsp;in&nbsp;after<br/>&nbsp;&nbsp;&nbsp;&nbsp;self.login.driver.quit()<br/>AttributeError:&nbsp;'LoginTest'&nbsp;object&nbsp;has&nbsp;no&nbsp;attribute&nbsp;'login'<br/><br/>During&nbsp;handling&nbsp;of&nbsp;the&nbsp;above&nbsp;exception,&nbsp;another&nbsp;exception&nbsp;occurred:<br/><br/>Traceback&nbsp;(most&nbsp;recent&nbsp;call&nbsp;last):<br/>&nbsp;&nbsp;File&nbsp;&quot;/Users/anderson/.pyenv/versions/3.5.3/lib/python3.5/site-packages/ptest/screencapturer.py&quot;,&nbsp;line&nbsp;332,&nbsp;in&nbsp;take_screenshot<br/>&nbsp;&nbsp;&nbsp;&nbsp;f.write(web_driver.get_screenshot_as_png())<br/>&nbsp;&nbsp;File&nbsp;&quot;/Users/anderson/.pyenv/versions/3.5.3/lib/python3.5/site-packages/selenium/webdriver/remote/webdriver.py&quot;,&nbsp;line&nbsp;817,&nbsp;in&nbsp;get_screenshot_as_png<br/>&nbsp;&nbsp;&nbsp;&nbsp;return&nbsp;base64.b64decode(self.get_screenshot_as_base64().encode('ascii'))<br/>&nbsp;&nbsp;File&nbsp;&quot;/Users/anderson/.pyenv/versions/3.5.3/lib/python3.5/site-packages/selenium/webdriver/remote/webdriver.py&quot;,&nbsp;line&nbsp;827,&nbsp;in&nbsp;get_screenshot_as_base64<br/>&nbsp;&nbsp;&nbsp;&nbsp;return&nbsp;self.execute(Command.SCREENSHOT)['value']<br/>&nbsp;&nbsp;File&nbsp;&quot;/Users/anderson/.pyenv/versions/3.5.3/lib/python3.5/site-packages/selenium/webdriver/remote/webdriver.py&quot;,&nbsp;line&nbsp;234,&nbsp;in&nbsp;execute<br/>&nbsp;&nbsp;&nbsp;&nbsp;response&nbsp;=&nbsp;self.command_executor.execute(driver_command,&nbsp;params)<br/>&nbsp;&nbsp;File&nbsp;&quot;/Users/anderson/.pyenv/versions/3.5.3/lib/python3.5/site-packages/selenium/webdriver/remote/remote_connection.py&quot;,&nbsp;line&nbsp;406,&nbsp;in&nbsp;execute<br/>&nbsp;&nbsp;&nbsp;&nbsp;path&nbsp;=&nbsp;string.Template(command_info[1]).substitute(params)<br/>&nbsp;&nbsp;File&nbsp;&quot;/Users/anderson/.pyenv/versions/3.5.3/lib/python3.5/string.py&quot;,&nbsp;line&nbsp;129,&nbsp;in&nbsp;substitute<br/>&nbsp;&nbsp;&nbsp;&nbsp;return&nbsp;self.pattern.sub(convert,&nbsp;self.template)<br/>&nbsp;&nbsp;File&nbsp;&quot;/Users/anderson/.pyenv/versions/3.5.3/lib/python3.5/string.py&quot;,&nbsp;line&nbsp;119,&nbsp;in&nbsp;convert<br/>&nbsp;&nbsp;&nbsp;&nbsp;val&nbsp;=&nbsp;mapping[named]<br/>TypeError:&nbsp;'NoneType'&nbsp;object&nbsp;is&nbsp;not&nbsp;subscriptable<br/>"}], "startTime": "2017-07-19 16:45:15.248748", "fullName": "autotest.cases.test_passcourse.LoginTest.pass_one_lesson@AfterMethod", "endTime": "2017-07-19 16:45:15.274217"}, "tags": [], "startTime": "2017-07-19 16:45:09.907704", "elapsedTime": 5.36659, "endTime": "2017-07-19 16:45:15.274294", "description": "", "beforeMethod": {"description": "Prepare test data.", "type": "fixture", "screenshots": [{"source": "Web&nbsp;Driver", "path": "autotest.cases.test_passcourse.LoginTest.pass_one_lesson@BeforeMethod-1.png"}], "elapsedTime": 5.340248, "fixtureType": "BeforeMethod", "status": "failed", "name": "setup_data", "logs": [{"level": "info", "message": "progress&nbsp;node&nbsp;was&nbsp;killed&nbsp;"}, {"level": "error", "message": "Failed&nbsp;with&nbsp;following&nbsp;message:<br/>Traceback&nbsp;(most&nbsp;recent&nbsp;call&nbsp;last):<br/>&nbsp;&nbsp;File&nbsp;&quot;/Users/anderson/.pyenv/versions/3.5.3/lib/python3.5/urllib/request.py&quot;,&nbsp;line&nbsp;1254,&nbsp;in&nbsp;do_open<br/>&nbsp;&nbsp;&nbsp;&nbsp;h.request(req.get_method(),&nbsp;req.selector,&nbsp;req.data,&nbsp;headers)<br/>&nbsp;&nbsp;File&nbsp;&quot;/Users/anderson/.pyenv/versions/3.5.3/lib/python3.5/http/client.py&quot;,&nbsp;line&nbsp;1107,&nbsp;in&nbsp;request<br/>&nbsp;&nbsp;&nbsp;&nbsp;self._send_request(method,&nbsp;url,&nbsp;body,&nbsp;headers)<br/>&nbsp;&nbsp;File&nbsp;&quot;/Users/anderson/.pyenv/versions/3.5.3/lib/python3.5/http/client.py&quot;,&nbsp;line&nbsp;1152,&nbsp;in&nbsp;_send_request<br/>&nbsp;&nbsp;&nbsp;&nbsp;self.endheaders(body)<br/>&nbsp;&nbsp;File&nbsp;&quot;/Users/anderson/.pyenv/versions/3.5.3/lib/python3.5/http/client.py&quot;,&nbsp;line&nbsp;1103,&nbsp;in&nbsp;endheaders<br/>&nbsp;&nbsp;&nbsp;&nbsp;self._send_output(message_body)<br/>&nbsp;&nbsp;File&nbsp;&quot;/Users/anderson/.pyenv/versions/3.5.3/lib/python3.5/http/client.py&quot;,&nbsp;line&nbsp;934,&nbsp;in&nbsp;_send_output<br/>&nbsp;&nbsp;&nbsp;&nbsp;self.send(msg)<br/>&nbsp;&nbsp;File&nbsp;&quot;/Users/anderson/.pyenv/versions/3.5.3/lib/python3.5/http/client.py&quot;,&nbsp;line&nbsp;877,&nbsp;in&nbsp;send<br/>&nbsp;&nbsp;&nbsp;&nbsp;self.connect()<br/>&nbsp;&nbsp;File&nbsp;&quot;/Users/anderson/.pyenv/versions/3.5.3/lib/python3.5/http/client.py&quot;,&nbsp;line&nbsp;849,&nbsp;in&nbsp;connect<br/>&nbsp;&nbsp;&nbsp;&nbsp;(self.host,self.port),&nbsp;self.timeout,&nbsp;self.source_address)<br/>&nbsp;&nbsp;File&nbsp;&quot;/Users/anderson/.pyenv/versions/3.5.3/lib/python3.5/socket.py&quot;,&nbsp;line&nbsp;712,&nbsp;in&nbsp;create_connection<br/>&nbsp;&nbsp;&nbsp;&nbsp;raise&nbsp;err<br/>&nbsp;&nbsp;File&nbsp;&quot;/Users/anderson/.pyenv/versions/3.5.3/lib/python3.5/socket.py&quot;,&nbsp;line&nbsp;703,&nbsp;in&nbsp;create_connection<br/>&nbsp;&nbsp;&nbsp;&nbsp;sock.connect(sa)<br/>ConnectionRefusedError:&nbsp;[Errno&nbsp;61]&nbsp;Connection&nbsp;refused<br/><br/>During&nbsp;handling&nbsp;of&nbsp;the&nbsp;above&nbsp;exception,&nbsp;another&nbsp;exception&nbsp;occurred:<br/><br/>Traceback&nbsp;(most&nbsp;recent&nbsp;call&nbsp;last):<br/>&nbsp;&nbsp;File&nbsp;&quot;/Users/anderson/.pyenv/versions/3.5.3/lib/python3.5/site-packages/ptest/testexecutor.py&quot;,&nbsp;line&nbsp;399,&nbsp;in&nbsp;run_test_configuration<br/>&nbsp;&nbsp;&nbsp;&nbsp;self.test_fixture.test_fixture_ref.__call__()<br/>&nbsp;&nbsp;File&nbsp;&quot;/Users/anderson/testcode/mobile_test/mynewthinking/autotest/cases/test_passcourse.py&quot;,&nbsp;line&nbsp;21,&nbsp;in&nbsp;setup_data<br/>&nbsp;&nbsp;&nbsp;&nbsp;self.login&nbsp;=&nbsp;Login()<br/>&nbsp;&nbsp;File&nbsp;&quot;/Users/anderson/testcode/mobile_test/mynewthinking/autotest/Base.py&quot;,&nbsp;line&nbsp;40,&nbsp;in&nbsp;__init__<br/>&nbsp;&nbsp;&nbsp;&nbsp;self.driver&nbsp;=&nbsp;webdriver.Remote('http://localhost:4723/wd/hub',&nbsp;self.capabilities)<br/>&nbsp;&nbsp;File&nbsp;&quot;/Users/anderson/.pyenv/versions/3.5.3/lib/python3.5/site-packages/appium/webdriver/webdriver.py&quot;,&nbsp;line&nbsp;36,&nbsp;in&nbsp;__init__<br/>&nbsp;&nbsp;&nbsp;&nbsp;super(WebDriver,&nbsp;self).__init__(command_executor,&nbsp;desired_capabilities,&nbsp;browser_profile,&nbsp;proxy,&nbsp;keep_alive)<br/>&nbsp;&nbsp;File&nbsp;&quot;/Users/anderson/.pyenv/versions/3.5.3/lib/python3.5/site-packages/selenium/webdriver/remote/webdriver.py&quot;,&nbsp;line&nbsp;92,&nbsp;in&nbsp;__init__<br/>&nbsp;&nbsp;&nbsp;&nbsp;self.start_session(desired_capabilities,&nbsp;browser_profile)<br/>&nbsp;&nbsp;File&nbsp;&quot;/Users/anderson/.pyenv/versions/3.5.3/lib/python3.5/site-packages/selenium/webdriver/remote/webdriver.py&quot;,&nbsp;line&nbsp;179,&nbsp;in&nbsp;start_session<br/>&nbsp;&nbsp;&nbsp;&nbsp;response&nbsp;=&nbsp;self.execute(Command.NEW_SESSION,&nbsp;capabilities)<br/>&nbsp;&nbsp;File&nbsp;&quot;/Users/anderson/.pyenv/versions/3.5.3/lib/python3.5/site-packages/selenium/webdriver/remote/webdriver.py&quot;,&nbsp;line&nbsp;234,&nbsp;in&nbsp;execute<br/>&nbsp;&nbsp;&nbsp;&nbsp;response&nbsp;=&nbsp;self.command_executor.execute(driver_command,&nbsp;params)<br/>&nbsp;&nbsp;File&nbsp;&quot;/Users/anderson/.pyenv/versions/3.5.3/lib/python3.5/site-packages/selenium/webdriver/remote/remote_connection.py&quot;,&nbsp;line&nbsp;408,&nbsp;in&nbsp;execute<br/>&nbsp;&nbsp;&nbsp;&nbsp;return&nbsp;self._request(command_info[0],&nbsp;url,&nbsp;body=data)<br/>&nbsp;&nbsp;File&nbsp;&quot;/Users/anderson/.pyenv/versions/3.5.3/lib/python3.5/site-packages/selenium/webdriver/remote/remote_connection.py&quot;,&nbsp;line&nbsp;478,&nbsp;in&nbsp;_request<br/>&nbsp;&nbsp;&nbsp;&nbsp;resp&nbsp;=&nbsp;opener.open(request,&nbsp;timeout=self._timeout)<br/>&nbsp;&nbsp;File&nbsp;&quot;/Users/anderson/.pyenv/versions/3.5.3/lib/python3.5/urllib/request.py&quot;,&nbsp;line&nbsp;466,&nbsp;in&nbsp;open<br/>&nbsp;&nbsp;&nbsp;&nbsp;response&nbsp;=&nbsp;self._open(req,&nbsp;data)<br/>&nbsp;&nbsp;File&nbsp;&quot;/Users/anderson/.pyenv/versions/3.5.3/lib/python3.5/urllib/request.py&quot;,&nbsp;line&nbsp;484,&nbsp;in&nbsp;_open<br/>&nbsp;&nbsp;&nbsp;&nbsp;'_open',&nbsp;req)<br/>&nbsp;&nbsp;File&nbsp;&quot;/Users/anderson/.pyenv/versions/3.5.3/lib/python3.5/urllib/request.py&quot;,&nbsp;line&nbsp;444,&nbsp;in&nbsp;_call_chain<br/>&nbsp;&nbsp;&nbsp;&nbsp;result&nbsp;=&nbsp;func(*args)<br/>&nbsp;&nbsp;File&nbsp;&quot;/Users/anderson/.pyenv/versions/3.5.3/lib/python3.5/urllib/request.py&quot;,&nbsp;line&nbsp;1282,&nbsp;in&nbsp;http_open<br/>&nbsp;&nbsp;&nbsp;&nbsp;return&nbsp;self.do_open(http.client.HTTPConnection,&nbsp;req)<br/>&nbsp;&nbsp;File&nbsp;&quot;/Users/anderson/.pyenv/versions/3.5.3/lib/python3.5/urllib/request.py&quot;,&nbsp;line&nbsp;1256,&nbsp;in&nbsp;do_open<br/>&nbsp;&nbsp;&nbsp;&nbsp;raise&nbsp;URLError(err)<br/>urllib.error.URLError:&nbsp;&lt;urlopen&nbsp;error&nbsp;[Errno&nbsp;61]&nbsp;Connection&nbsp;refused&gt;<br/>"}, {"level": "warning", "message": "Failed&nbsp;to&nbsp;take&nbsp;the&nbsp;screenshot.<br/>Traceback&nbsp;(most&nbsp;recent&nbsp;call&nbsp;last):<br/>&nbsp;&nbsp;File&nbsp;&quot;/Users/anderson/.pyenv/versions/3.5.3/lib/python3.5/urllib/request.py&quot;,&nbsp;line&nbsp;1254,&nbsp;in&nbsp;do_open<br/>&nbsp;&nbsp;&nbsp;&nbsp;h.request(req.get_method(),&nbsp;req.selector,&nbsp;req.data,&nbsp;headers)<br/>&nbsp;&nbsp;File&nbsp;&quot;/Users/anderson/.pyenv/versions/3.5.3/lib/python3.5/http/client.py&quot;,&nbsp;line&nbsp;1107,&nbsp;in&nbsp;request<br/>&nbsp;&nbsp;&nbsp;&nbsp;self._send_request(method,&nbsp;url,&nbsp;body,&nbsp;headers)<br/>&nbsp;&nbsp;File&nbsp;&quot;/Users/anderson/.pyenv/versions/3.5.3/lib/python3.5/http/client.py&quot;,&nbsp;line&nbsp;1152,&nbsp;in&nbsp;_send_request<br/>&nbsp;&nbsp;&nbsp;&nbsp;self.endheaders(body)<br/>&nbsp;&nbsp;File&nbsp;&quot;/Users/anderson/.pyenv/versions/3.5.3/lib/python3.5/http/client.py&quot;,&nbsp;line&nbsp;1103,&nbsp;in&nbsp;endheaders<br/>&nbsp;&nbsp;&nbsp;&nbsp;self._send_output(message_body)<br/>&nbsp;&nbsp;File&nbsp;&quot;/Users/anderson/.pyenv/versions/3.5.3/lib/python3.5/http/client.py&quot;,&nbsp;line&nbsp;934,&nbsp;in&nbsp;_send_output<br/>&nbsp;&nbsp;&nbsp;&nbsp;self.send(msg)<br/>&nbsp;&nbsp;File&nbsp;&quot;/Users/anderson/.pyenv/versions/3.5.3/lib/python3.5/http/client.py&quot;,&nbsp;line&nbsp;877,&nbsp;in&nbsp;send<br/>&nbsp;&nbsp;&nbsp;&nbsp;self.connect()<br/>&nbsp;&nbsp;File&nbsp;&quot;/Users/anderson/.pyenv/versions/3.5.3/lib/python3.5/http/client.py&quot;,&nbsp;line&nbsp;849,&nbsp;in&nbsp;connect<br/>&nbsp;&nbsp;&nbsp;&nbsp;(self.host,self.port),&nbsp;self.timeout,&nbsp;self.source_address)<br/>&nbsp;&nbsp;File&nbsp;&quot;/Users/anderson/.pyenv/versions/3.5.3/lib/python3.5/socket.py&quot;,&nbsp;line&nbsp;712,&nbsp;in&nbsp;create_connection<br/>&nbsp;&nbsp;&nbsp;&nbsp;raise&nbsp;err<br/>&nbsp;&nbsp;File&nbsp;&quot;/Users/anderson/.pyenv/versions/3.5.3/lib/python3.5/socket.py&quot;,&nbsp;line&nbsp;703,&nbsp;in&nbsp;create_connection<br/>&nbsp;&nbsp;&nbsp;&nbsp;sock.connect(sa)<br/>ConnectionRefusedError:&nbsp;[Errno&nbsp;61]&nbsp;Connection&nbsp;refused<br/><br/>During&nbsp;handling&nbsp;of&nbsp;the&nbsp;above&nbsp;exception,&nbsp;another&nbsp;exception&nbsp;occurred:<br/><br/>Traceback&nbsp;(most&nbsp;recent&nbsp;call&nbsp;last):<br/>&nbsp;&nbsp;File&nbsp;&quot;/Users/anderson/.pyenv/versions/3.5.3/lib/python3.5/site-packages/ptest/testexecutor.py&quot;,&nbsp;line&nbsp;399,&nbsp;in&nbsp;run_test_configuration<br/>&nbsp;&nbsp;&nbsp;&nbsp;self.test_fixture.test_fixture_ref.__call__()<br/>&nbsp;&nbsp;File&nbsp;&quot;/Users/anderson/testcode/mobile_test/mynewthinking/autotest/cases/test_passcourse.py&quot;,&nbsp;line&nbsp;21,&nbsp;in&nbsp;setup_data<br/>&nbsp;&nbsp;&nbsp;&nbsp;self.login&nbsp;=&nbsp;Login()<br/>&nbsp;&nbsp;File&nbsp;&quot;/Users/anderson/testcode/mobile_test/mynewthinking/autotest/Base.py&quot;,&nbsp;line&nbsp;40,&nbsp;in&nbsp;__init__<br/>&nbsp;&nbsp;&nbsp;&nbsp;self.driver&nbsp;=&nbsp;webdriver.Remote('http://localhost:4723/wd/hub',&nbsp;self.capabilities)<br/>&nbsp;&nbsp;File&nbsp;&quot;/Users/anderson/.pyenv/versions/3.5.3/lib/python3.5/site-packages/appium/webdriver/webdriver.py&quot;,&nbsp;line&nbsp;36,&nbsp;in&nbsp;__init__<br/>&nbsp;&nbsp;&nbsp;&nbsp;super(WebDriver,&nbsp;self).__init__(command_executor,&nbsp;desired_capabilities,&nbsp;browser_profile,&nbsp;proxy,&nbsp;keep_alive)<br/>&nbsp;&nbsp;File&nbsp;&quot;/Users/anderson/.pyenv/versions/3.5.3/lib/python3.5/site-packages/selenium/webdriver/remote/webdriver.py&quot;,&nbsp;line&nbsp;92,&nbsp;in&nbsp;__init__<br/>&nbsp;&nbsp;&nbsp;&nbsp;self.start_session(desired_capabilities,&nbsp;browser_profile)<br/>&nbsp;&nbsp;File&nbsp;&quot;/Users/anderson/.pyenv/versions/3.5.3/lib/python3.5/site-packages/selenium/webdriver/remote/webdriver.py&quot;,&nbsp;line&nbsp;179,&nbsp;in&nbsp;start_session<br/>&nbsp;&nbsp;&nbsp;&nbsp;response&nbsp;=&nbsp;self.execute(Command.NEW_SESSION,&nbsp;capabilities)<br/>&nbsp;&nbsp;File&nbsp;&quot;/Users/anderson/.pyenv/versions/3.5.3/lib/python3.5/site-packages/selenium/webdriver/remote/webdriver.py&quot;,&nbsp;line&nbsp;234,&nbsp;in&nbsp;execute<br/>&nbsp;&nbsp;&nbsp;&nbsp;response&nbsp;=&nbsp;self.command_executor.execute(driver_command,&nbsp;params)<br/>&nbsp;&nbsp;File&nbsp;&quot;/Users/anderson/.pyenv/versions/3.5.3/lib/python3.5/site-packages/selenium/webdriver/remote/remote_connection.py&quot;,&nbsp;line&nbsp;408,&nbsp;in&nbsp;execute<br/>&nbsp;&nbsp;&nbsp;&nbsp;return&nbsp;self._request(command_info[0],&nbsp;url,&nbsp;body=data)<br/>&nbsp;&nbsp;File&nbsp;&quot;/Users/anderson/.pyenv/versions/3.5.3/lib/python3.5/site-packages/selenium/webdriver/remote/remote_connection.py&quot;,&nbsp;line&nbsp;478,&nbsp;in&nbsp;_request<br/>&nbsp;&nbsp;&nbsp;&nbsp;resp&nbsp;=&nbsp;opener.open(request,&nbsp;timeout=self._timeout)<br/>&nbsp;&nbsp;File&nbsp;&quot;/Users/anderson/.pyenv/versions/3.5.3/lib/python3.5/urllib/request.py&quot;,&nbsp;line&nbsp;466,&nbsp;in&nbsp;open<br/>&nbsp;&nbsp;&nbsp;&nbsp;response&nbsp;=&nbsp;self._open(req,&nbsp;data)<br/>&nbsp;&nbsp;File&nbsp;&quot;/Users/anderson/.pyenv/versions/3.5.3/lib/python3.5/urllib/request.py&quot;,&nbsp;line&nbsp;484,&nbsp;in&nbsp;_open<br/>&nbsp;&nbsp;&nbsp;&nbsp;'_open',&nbsp;req)<br/>&nbsp;&nbsp;File&nbsp;&quot;/Users/anderson/.pyenv/versions/3.5.3/lib/python3.5/urllib/request.py&quot;,&nbsp;line&nbsp;444,&nbsp;in&nbsp;_call_chain<br/>&nbsp;&nbsp;&nbsp;&nbsp;result&nbsp;=&nbsp;func(*args)<br/>&nbsp;&nbsp;File&nbsp;&quot;/Users/anderson/.pyenv/versions/3.5.3/lib/python3.5/urllib/request.py&quot;,&nbsp;line&nbsp;1282,&nbsp;in&nbsp;http_open<br/>&nbsp;&nbsp;&nbsp;&nbsp;return&nbsp;self.do_open(http.client.HTTPConnection,&nbsp;req)<br/>&nbsp;&nbsp;File&nbsp;&quot;/Users/anderson/.pyenv/versions/3.5.3/lib/python3.5/urllib/request.py&quot;,&nbsp;line&nbsp;1256,&nbsp;in&nbsp;do_open<br/>&nbsp;&nbsp;&nbsp;&nbsp;raise&nbsp;URLError(err)<br/>urllib.error.URLError:&nbsp;&lt;urlopen&nbsp;error&nbsp;[Errno&nbsp;61]&nbsp;Connection&nbsp;refused&gt;<br/><br/>During&nbsp;handling&nbsp;of&nbsp;the&nbsp;above&nbsp;exception,&nbsp;another&nbsp;exception&nbsp;occurred:<br/><br/>Traceback&nbsp;(most&nbsp;recent&nbsp;call&nbsp;last):<br/>&nbsp;&nbsp;File&nbsp;&quot;/Users/anderson/.pyenv/versions/3.5.3/lib/python3.5/site-packages/ptest/screencapturer.py&quot;,&nbsp;line&nbsp;332,&nbsp;in&nbsp;take_screenshot<br/>&nbsp;&nbsp;&nbsp;&nbsp;f.write(web_driver.get_screenshot_as_png())<br/>&nbsp;&nbsp;File&nbsp;&quot;/Users/anderson/.pyenv/versions/3.5.3/lib/python3.5/site-packages/selenium/webdriver/remote/webdriver.py&quot;,&nbsp;line&nbsp;817,&nbsp;in&nbsp;get_screenshot_as_png<br/>&nbsp;&nbsp;&nbsp;&nbsp;return&nbsp;base64.b64decode(self.get_screenshot_as_base64().encode('ascii'))<br/>&nbsp;&nbsp;File&nbsp;&quot;/Users/anderson/.pyenv/versions/3.5.3/lib/python3.5/site-packages/selenium/webdriver/remote/webdriver.py&quot;,&nbsp;line&nbsp;827,&nbsp;in&nbsp;get_screenshot_as_base64<br/>&nbsp;&nbsp;&nbsp;&nbsp;return&nbsp;self.execute(Command.SCREENSHOT)['value']<br/>&nbsp;&nbsp;File&nbsp;&quot;/Users/anderson/.pyenv/versions/3.5.3/lib/python3.5/site-packages/selenium/webdriver/remote/webdriver.py&quot;,&nbsp;line&nbsp;234,&nbsp;in&nbsp;execute<br/>&nbsp;&nbsp;&nbsp;&nbsp;response&nbsp;=&nbsp;self.command_executor.execute(driver_command,&nbsp;params)<br/>&nbsp;&nbsp;File&nbsp;&quot;/Users/anderson/.pyenv/versions/3.5.3/lib/python3.5/site-packages/selenium/webdriver/remote/remote_connection.py&quot;,&nbsp;line&nbsp;406,&nbsp;in&nbsp;execute<br/>&nbsp;&nbsp;&nbsp;&nbsp;path&nbsp;=&nbsp;string.Template(command_info[1]).substitute(params)<br/>&nbsp;&nbsp;File&nbsp;&quot;/Users/anderson/.pyenv/versions/3.5.3/lib/python3.5/string.py&quot;,&nbsp;line&nbsp;129,&nbsp;in&nbsp;substitute<br/>&nbsp;&nbsp;&nbsp;&nbsp;return&nbsp;self.pattern.sub(convert,&nbsp;self.template)<br/>&nbsp;&nbsp;File&nbsp;&quot;/Users/anderson/.pyenv/versions/3.5.3/lib/python3.5/string.py&quot;,&nbsp;line&nbsp;119,&nbsp;in&nbsp;convert<br/>&nbsp;&nbsp;&nbsp;&nbsp;val&nbsp;=&nbsp;mapping[named]<br/>TypeError:&nbsp;'NoneType'&nbsp;object&nbsp;is&nbsp;not&nbsp;subscriptable<br/>"}], "startTime": "2017-07-19 16:45:09.907836", "fullName": "autotest.cases.test_passcourse.LoginTest.pass_one_lesson@BeforeMethod", "endTime": "2017-07-19 16:45:15.248084"}, "group": "DEFAULT", "status": "skipped", "name": "pass_one_lesson", "fullName": "autotest.cases.test_passcourse.LoginTest.pass_one_lesson"}], "total": 1, "fullName": "autotest.cases.test_passcourse.LoginTest"}], "name": "test_passcourse", "total": 1, "passed": 0, "fullName": "autotest.cases.test_passcourse", "failed": 0}], "testClasses": [], "name": "cases", "total": 1, "passed": 0, "fullName": "autotest.cases", "failed": 0}], "testClasses": [], "name": "autotest", "total": 1, "passed": 0, "fullName": "autotest", "failed": 0}], "passed": 0, "name": "DefaultSuite", "failed": 0, "total": 1, "startTime": "2017-07-19 16:45:09.906392", "fullName": "DefaultSuite", "endTime": "2017-07-19 16:45:15.275341"};
</script>
</body>
</html>